<?xml version='1.0'?>
<sdf version='1.4'>
  <model name="my_robot">
	<static>false</static>

	<link name='chassis'>
            <pose>0 0 1 0 0 0</pose>

            <collision name='collision'>
              <geometry>
                <box>
                  <size>.4 .2 .05</size>
                </box>
              </geometry>
            </collision>

            <visual name='visual'>
              <geometry>
                <box>
                  <size>.4 .2 .05</size>
                </box>
              </geometry>
            </visual>
		
		
          </link>

	 <link name="frontleft_leg">
        	<pose>0.18 0.08 0.75 0 0 0</pose>
        	<collision name="collision">
          		<geometry>
           			<cylinder>
              				<radius>.025</radius>
              				<length>0.5</length>
            			</cylinder>
          		</geometry>
        	</collision>
        
		<visual name="visual">
          		<geometry>
           			<cylinder>
              				<radius>.025</radius>
              				<length>0.5</length>
            			</cylinder>
          		</geometry>
        	</visual>
      	</link>


	 <link name="frontleft_calf">
        	<pose>0.18 0.08 0.25 0 0 0</pose>
        	<collision name="collision">
          		<geometry>
           			<cylinder>
              				<radius>.025</radius>
              				<length>0.5</length>
            			</cylinder>
          		</geometry>
        	</collision>
        
		<visual name="visual">
          		<geometry>
           			<cylinder>
              				<radius>.025</radius>
              				<length>0.5</length>
            			</cylinder>
          		</geometry>
        	</visual>
      	</link>


	<link name="frontright_leg">
        	<pose>0.18 -0.08 0.75 0 0 0</pose>
        	<collision name="collision">
          		<geometry>
           			<cylinder>
              				<radius>.025</radius>
              				<length>0.5</length>
            			</cylinder>
          		</geometry>
        	</collision>
        
		<visual name="visual">
          		<geometry>
           			<cylinder>
              				<radius>.025</radius>
              				<length>0.5</length>
            			</cylinder>
          		</geometry>
        	</visual>
      	</link>

	<link name="frontright_calf">
        	<pose>0.18 -0.08 0.25 0 0 0</pose>
        	<collision name="collision">
          		<geometry>
           			<cylinder>
              				<radius>.025</radius>
              				<length>0.5</length>
            			</cylinder>
          		</geometry>
        	</collision>
        
		<visual name="visual">
          		<geometry>
           			<cylinder>
              				<radius>.025</radius>
              				<length>0.5</length>
            			</cylinder>
          		</geometry>
        	</visual>
      	</link>

	<link name="backleft_leg">
        	<pose>-0.18 0.08 0.75 0 0 0</pose>
        	<collision name="collision">
          		<geometry>
           			<cylinder>
              				<radius>.025</radius>
              				<length>0.5</length>
            			</cylinder>
          		</geometry>
        	</collision>
        
		<visual name="visual">
          		<geometry>
           			<cylinder>
              				<radius>.025</radius>
              				<length>0.5</length>
            			</cylinder>
          		</geometry>
        	</visual>
      	</link>

	<link name="backleft_calf">
        	<pose>-0.18 0.08 0.25 0 0 0</pose>
        	<collision name="collision">
          		<geometry>
           			<cylinder>
              				<radius>.025</radius>
              				<length>0.5</length>
            			</cylinder>
          		</geometry>
        	</collision>
        
		<visual name="visual">
          		<geometry>
           			<cylinder>
              				<radius>.025</radius>
              				<length>0.5</length>
            			</cylinder>
          		</geometry>
        	</visual>
      	</link>

	<link name="backright_leg">
        	<pose>-0.18 -0.08 0.75 0 0 0</pose>
        	<collision name="collision">
          		<geometry>
           			<cylinder>
              				<radius>.025</radius>
              				<length>0.5</length>
            			</cylinder>
          		</geometry>
        	</collision>
        
		<visual name="visual">
          		<geometry>
           			<cylinder>
              				<radius>.025</radius>
              				<length>0.5</length>
            			</cylinder>
          		</geometry>
        	</visual>
      	</link>

	<link name="backright_calf">
        	<pose>-0.18 -0.08 0.25 0 0 0</pose>
        	<collision name="collision">
          		<geometry>
           			<cylinder>
              				<radius>.025</radius>
              				<length>0.5</length>
            			</cylinder>
          		</geometry>
        	</collision>
        
		<visual name="visual">
          		<geometry>
           			<cylinder>
              				<radius>.025</radius>
              				<length>0.5</length>
            			</cylinder>
          		</geometry>
        	</visual>
      	</link>

	<joint type="revolute" name="frontleft_hip">
        	<pose>0 0 0.25 0 0 0</pose>
        	<child>frontleft_leg</child>
        	<parent>chassis</parent>
        	<axis>
          		<xyz>0 1 0</xyz>
        	</axis>
       </joint>


	<joint type="revolute" name="frontleft_knee">
        	<pose>0 0 0.25 0 0 0</pose>
        	<child>frontleft_calf</child>
        	<parent>frontleft_leg</parent>
        	<axis>
          		<xyz>0 1 0</xyz>
        	</axis>
       </joint>

	<joint type="revolute" name="frontright_hip">
        	<pose>0 0 0.25 0 0 0</pose>
        	<child>frontright_leg</child>
        	<parent>chassis</parent>
        	<axis>
          		<xyz>0 1 0</xyz>
        	</axis>
       </joint>

	<joint type="revolute" name="frontright_knee">
        	<pose>0 0 0.25 0 0 0</pose>
        	<child>frontright_calf</child>
        	<parent>frontright_leg</parent>
        	<axis>
          		<xyz>0 1 0</xyz>
        	</axis>
       </joint>

	<joint type="revolute" name="backleft_hip">
        	<pose>0 0 0.25 0 0 0</pose>
        	<child>backleft_leg</child>
        	<parent>chassis</parent>
        	<axis>
          		<xyz>0 1 0</xyz>
        	</axis>
       </joint>

	<joint type="revolute" name="backleft_knee">
        	<pose>0 0 0.25 0 0 0</pose>
        	<child>backleft_calf</child>
        	<parent>backleft_leg</parent>
        	<axis>
          		<xyz>0 1 0</xyz>
        	</axis>
       </joint>

	<joint type="revolute" name="backright_hip">
        	<pose>0 0 0.25 0 0 0</pose>
        	<child>backright_leg</child>
        	<parent>chassis</parent>
        	<axis>
          		<xyz>0 1 0</xyz>
        	</axis>
       </joint>

	<joint type="revolute" name="backright_knee">
        	<pose>0 0 0.25 0 0 0</pose>
        	<child>backright_calf</child>
        	<parent>backright_leg</parent>
        	<axis>
          		<xyz>0 1 0</xyz>
        	</axis>
       </joint>
	
  </model>
</sdf>
